Pig Stack Trace
---------------
ERROR 1002: Unable to store alias outtest

org.apache.pig.impl.logicalLayer.FrontendException: ERROR 1066: Unable to open iterator for alias outtest
	at org.apache.pig.PigServer.openIterator(PigServer.java:912)
	at org.apache.pig.tools.grunt.GruntParser.processDump(GruntParser.java:752)
	at org.apache.pig.tools.pigscript.parser.PigScriptParser.parse(PigScriptParser.java:372)
	at org.apache.pig.tools.grunt.GruntParser.parseStopOnError(GruntParser.java:228)
	at org.apache.pig.tools.grunt.GruntParser.parseStopOnError(GruntParser.java:203)
	at org.apache.pig.tools.grunt.Grunt.run(Grunt.java:66)
	at org.apache.pig.Main.run(Main.java:542)
	at org.apache.pig.Main.main(Main.java:156)
	at sun.reflect.NativeMethodAccessorImpl.invoke0(Native Method)
	at sun.reflect.NativeMethodAccessorImpl.invoke(NativeMethodAccessorImpl.java:57)
	at sun.reflect.DelegatingMethodAccessorImpl.invoke(DelegatingMethodAccessorImpl.java:43)
	at java.lang.reflect.Method.invoke(Method.java:601)
	at org.apache.hadoop.util.RunJar.main(RunJar.java:212)
Caused by: org.apache.pig.PigException: ERROR 1002: Unable to store alias outtest
	at org.apache.pig.PigServer.storeEx(PigServer.java:1015)
	at org.apache.pig.PigServer.store(PigServer.java:974)
	at org.apache.pig.PigServer.openIterator(PigServer.java:887)
	... 12 more
Caused by: org.apache.pig.backend.executionengine.ExecException: ERROR 0: Exception while executing (Name: outtest: Store(hdfs://cluster.cusp.nyu.edu:9000/tmp/temp-1450939095/tmp-152123773:org.apache.pig.impl.io.InterStorage) - scope-3 Operator Key: scope-3): org.apache.pig.impl.streaming.StreamingUDFException: LINE : Traceback (most recent call last):
  File "/tmp/controller7118559747824681817.py", line 338, in <module>
    sys.argv[5], sys.argv[6], sys.argv[7], sys.argv[8])
  File "/tmp/controller7118559747824681817.py", line 77, in main
    self.output_stream = open(output_stream_path, 'a')
IOError: [Errno 2] No such file or directory: '/localhome/hdfs/logs/udfOutput/test.out'

	at org.apache.pig.backend.hadoop.executionengine.physicalLayer.PhysicalOperator.processInput(PhysicalOperator.java:289)
	at org.apache.pig.backend.hadoop.executionengine.physicalLayer.relationalOperators.POStore.getNextTuple(POStore.java:143)
	at org.apache.pig.backend.hadoop.executionengine.fetch.FetchLauncher.runPipeline(FetchLauncher.java:160)
	at org.apache.pig.backend.hadoop.executionengine.fetch.FetchLauncher.launchPig(FetchLauncher.java:81)
	at org.apache.pig.backend.hadoop.executionengine.HExecutionEngine.launchPig(HExecutionEngine.java:275)
	at org.apache.pig.PigServer.launchPlan(PigServer.java:1367)
	at org.apache.pig.PigServer.executeCompiledLogicalPlan(PigServer.java:1352)
	at org.apache.pig.PigServer.storeEx(PigServer.java:1011)
	... 14 more
Caused by: org.apache.pig.impl.streaming.StreamingUDFException: LINE : Traceback (most recent call last):
  File "/tmp/controller7118559747824681817.py", line 338, in <module>
    sys.argv[5], sys.argv[6], sys.argv[7], sys.argv[8])
  File "/tmp/controller7118559747824681817.py", line 77, in main
    self.output_stream = open(output_stream_path, 'a')
IOError: [Errno 2] No such file or directory: '/localhome/hdfs/logs/udfOutput/test.out'

	at org.apache.pig.impl.builtin.StreamingUDF$ProcessErrorThread.run(StreamingUDF.java:459)
================================================================================
